{"trial_id": "0000", "hyperparameters": {"space": [{"class_name": "Int", "config": {"name": "units", "default": null, "conditions": [], "min_value": 32, "max_value": 512, "step": 32, "sampling": "linear"}}, {"class_name": "Choice", "config": {"name": "learning_rate", "default": 0.01, "conditions": [], "values": [0.01, 0.001, 0.0001], "ordered": true}}], "values": {"units": 352, "learning_rate": 0.01, "tuner/epochs": 2, "tuner/initial_epoch": 0, "tuner/bracket": 2, "tuner/round": 0}}, "metrics": {"metrics": {}}, "score": null, "best_step": 0, "status": "FAILED", "message": "Traceback (most recent call last):\n  File \"C:\\Users\\zoric\\AppData\\Local\\Programs\\Python\\Python310\\lib\\site-packages\\keras_tuner\\src\\engine\\base_tuner.py\", line 273, in _try_run_and_update_trial\n    self._run_and_update_trial(trial, *fit_args, **fit_kwargs)\n  File \"C:\\Users\\zoric\\AppData\\Local\\Programs\\Python\\Python310\\lib\\site-packages\\keras_tuner\\src\\engine\\base_tuner.py\", line 238, in _run_and_update_trial\n    results = self.run_trial(trial, *fit_args, **fit_kwargs)\n  File \"C:\\Users\\zoric\\AppData\\Local\\Programs\\Python\\Python310\\lib\\site-packages\\keras_tuner\\src\\tuners\\hyperband.py\", line 427, in run_trial\n    return super().run_trial(trial, *fit_args, **fit_kwargs)\n  File \"C:\\Users\\zoric\\AppData\\Local\\Programs\\Python\\Python310\\lib\\site-packages\\keras_tuner\\src\\engine\\tuner.py\", line 314, in run_trial\n    obj_value = self._build_and_fit_model(trial, *args, **copied_kwargs)\n  File \"C:\\Users\\zoric\\AppData\\Local\\Programs\\Python\\Python310\\lib\\site-packages\\keras_tuner\\src\\engine\\tuner.py\", line 233, in _build_and_fit_model\n    results = self.hypermodel.fit(hp, model, *args, **kwargs)\n  File \"C:\\Users\\zoric\\AppData\\Local\\Programs\\Python\\Python310\\lib\\site-packages\\keras_tuner\\src\\engine\\hypermodel.py\", line 149, in fit\n    return model.fit(*args, **kwargs)\n  File \"C:\\Users\\zoric\\AppData\\Local\\Programs\\Python\\Python310\\lib\\site-packages\\keras\\utils\\traceback_utils.py\", line 67, in error_handler\n    raise e.with_traceback(filtered_tb) from None\n  File \"C:\\Users\\zoric\\AppData\\Roaming\\Python\\Python310\\site-packages\\tensorflow\\python\\framework\\func_graph.py\", line 1147, in autograph_handler\n    raise e.ag_error_metadata.to_exception(e)\nValueError: in user code:\n\n    File \"C:\\Users\\zoric\\AppData\\Local\\Programs\\Python\\Python310\\lib\\site-packages\\keras\\engine\\training.py\", line 1021, in train_function  *\n        return step_function(self, iterator)\n    File \"C:\\Users\\zoric\\AppData\\Local\\Programs\\Python\\Python310\\lib\\site-packages\\keras\\engine\\training.py\", line 1010, in step_function  **\n        outputs = model.distribute_strategy.run(run_step, args=(data,))\n    File \"C:\\Users\\zoric\\AppData\\Local\\Programs\\Python\\Python310\\lib\\site-packages\\keras\\engine\\training.py\", line 1000, in run_step  **\n        outputs = model.train_step(data)\n    File \"C:\\Users\\zoric\\AppData\\Local\\Programs\\Python\\Python310\\lib\\site-packages\\keras\\engine\\training.py\", line 859, in train_step\n        y_pred = self(x, training=True)\n    File \"C:\\Users\\zoric\\AppData\\Local\\Programs\\Python\\Python310\\lib\\site-packages\\keras\\utils\\traceback_utils.py\", line 67, in error_handler\n        raise e.with_traceback(filtered_tb) from None\n    File \"C:\\Users\\zoric\\AppData\\Local\\Programs\\Python\\Python310\\lib\\site-packages\\keras\\engine\\input_spec.py\", line 264, in assert_input_compatibility\n        raise ValueError(f'Input {input_index} of layer \"{layer_name}\" is '\n\n    ValueError: Input 0 of layer \"sequential\" is incompatible with the layer: expected shape=(None, 28, 28), found shape=(None, 45)\n\n"}